Workbook

Sheet Bond_Diff_2001
A1: Time | B1: AT | C1: BE | D1: CY | E1: CZ | F1: DE | G1: DK | H1: EL | I1: ES | J1: FI | K1: FR | L1: HU | M1: IE | N1: IT | O1: LT | P1: LU | Q1: LV | R1: MT | S1: NL | T1: PL | U1: PT | V1: SE | W1: SK | X1: UK | Y1: JP | Z1: US
A2: 2001-02 | B2: =Bond_2001!B3-Bond_2001!B2 -> 0 | C2: =Bond_2001!C3-Bond_2001!C2 -> 0 | D2: =Bond_2001!D3-Bond_2001!D2 -> 0 | E2: =Bond_2001!E3-Bond_2001!E2 -> -0.32 | F2: =Bond_2001!F3-Bond_2001!F2 -> -0.02 | G2: =Bond_2001!G3-Bond_2001!G2 -> -0.03 | H2: =Bond_2001!H3-Bond_2001!H2 -> 0 | I2: =Bond_2001!I3-Bond_2001!I2 -> 0.04 | ... Z2: =Bond_2001!Z3-Bond_2001!Z2 -> -0.0432
A3: 2001-03 | B3: =Bond_2001!B4-Bond_2001!B3 -> -0.09 | C3: =Bond_2001!C4-Bond_2001!C3 -> -0.08 | D3: =Bond_2001!D4-Bond_2001!D3 -> -0.02 | E3: =Bond_2001!E4-Bond_2001!E3 -> -0.26 | F3: =Bond_2001!F4-Bond_2001!F3 -> -0.11 | G3: =Bond_2001!G4-Bond_2001!G3 -> -0.11 | H3: =Bond_2001!H4-Bond_2001!H3 -> -0.07 | I3: =Bond_2001!I4-Bond_2001!I3 -> -0.08 | ... Z3: =Bond_2001!Z4-Bond_2001!Z3 -> -0.2165
A4: 2001-04 | B4: =Bond_2001!B5-Bond_2001!B4 -> 0.15 | C4: =Bond_2001!C5-Bond_2001!C4 -> 0.13 | D4: =Bond_2001!D5-Bond_2001!D4 -> -0.03 | E4: =Bond_2001!E5-Bond_2001!E4 -> 0.01 | F4: =Bond_2001!F5-Bond_2001!F4 -> 0.16 | G4: =Bond_2001!G5-Bond_2001!G4 -> 0.19 | H4: =Bond_2001!H5-Bond_2001!H4 -> 0.11 | I4: =Bond_2001!I5-Bond_2001!I4 -> 0.14 | ... Z4: =Bond_2001!Z5-Bond_2001!Z4 -> 0.2428
A5: 2001-05 | B5: =Bond_2001!B6-Bond_2001!B5 -> 0.18 | C5: =Bond_2001!C6-Bond_2001!C5 -> 0.17 | D5: =Bond_2001!D6-Bond_2001!D5 -> 0.08 | E5: =Bond_2001!E6-Bond_2001!E5 -> 0.24 | F5: =Bond_2001!F6-Bond_2001!F5 -> 0.22 | G5: =Bond_2001!G6-Bond_2001!G5 -> 0.21 | H5: =Bond_2001!H6-Bond_2001!H5 -> 0.15 | I5: =Bond_2001!I6-Bond_2001!I5 -> 0.18 | ... Z5: =Bond_2001!Z6-Bond_2001!Z5 -> 0.2402
A6: 2001-06 | B6: =Bond_2001!B7-Bond_2001!B6 -> -0.07 | C6: =Bond_2001!C7-Bond_2001!C6 -> -0.05 | D6: =Bond_2001!D7-Bond_2001!D6 -> -0.01 | E6: =Bond_2001!E7-Bond_2001!E6 -> 0.23 | F6: =Bond_2001!F7-Bond_2001!F6 -> -0.05 | G6: =Bond_2001!G7-Bond_2001!G6 -> -0.02 | H6: =Bond_2001!H7-Bond_2001!H6 -> -0.06 | I6: =Bond_2001!I7-Bond_2001!I6 -> -0.03 | ... Z6: =Bond_2001!Z7-Bond_2001!Z6 -> -0.1094
A7: 2001-07 | B7: =Bond_2001!B8-Bond_2001!B7 -> 0.02 | C7: =Bond_2001!C8-Bond_2001!C7 -> 0.02 | D7: =Bond_2001!D8-Bond_2001!D7 -> -0.01 | E7: =Bond_2001!E8-Bond_2001!E7 -> 0.13 | F7: =Bond_2001!F8-Bond_2001!F7 -> 0.02 | G7: =Bond_2001!G8-Bond_2001!G7 -> -0.01 | H7: =Bond_2001!H8-Bond_2001!H7 -> 0.03 | I7: =Bond_2001!I8-Bond_2001!I7 -> 0.02 | ... Z7: =Bond_2001!Z8-Bond_2001!Z7 -> -0.0334
A8: 2001-08 | B8: =Bond_2001!B9-Bond_2001!B8 -> -0.19 | C8: =Bond_2001!C9-Bond_2001!C8 -> -0.2 | D8: =Bond_2001!D9-Bond_2001!D8 -> -0.14 | E8: =Bond_2001!E9-Bond_2001!E8 -> -0.09 | F8: =Bond_2001!F9-Bond_2001!F8 -> -0.2 | G8: =Bond_2001!G9-Bond_2001!G8 -> -0.2 | H8: =Bond_2001!H9-Bond_2001!H8 -> -0.18 | I8: =Bond_2001!I9-Bond_2001!I8 -> -0.19 | ... Z8: =Bond_2001!Z9-Bond_2001!Z8 -> -0.2528
A9: 2001-09 | B9: =Bond_2001!B10-Bond_2001!B9 -> -0.02 | C9: =Bond_2001!C10-Bond_2001!C9 -> -0.01 | D9: =Bond_2001!D10-Bond_2001!D9 -> 0 | E9: =Bond_2001!E10-Bond_2001!E9 -> -0.29 | F9: =Bond_2001!F10-Bond_2001!F9 -> -0.01 | G9: =Bond_2001!G10-Bond_2001!G9 -> -0.01 | H9: =Bond_2001!H10-Bond_2001!H9 -> -0.02 | I9: =Bond_2001!I10-Bond_2001!I9 -> -0.02 | ... Z9: =Bond_2001!Z10-Bond_2001!Z9 -> -0.2173
A10: 2001-10 | B10: =Bond_2001!B11-Bond_2001!B10 -> -0.23 | C10: =Bond_2001!C11-Bond_2001!C10 -> -0.25 | D10: =Bond_2001!D11-Bond_2001!D10 -> 0 | E10: =Bond_2001!E11-Bond_2001!E10 -> -0.63 | F10: =Bond_2001!F11-Bond_2001!F10 -> -0.21 | G10: =Bond_2001!G11-Bond_2001!G10 -> -0.25 | H10: =Bond_2001!H11-Bond_2001!H10 -> -0.24 | I10: =Bond_2001!I11-Bond_2001!I10 -> -0.23 | ... Z10: =Bond_2001!Z11-Bond_2001!Z10 -> -0.2006
A11: 2001-11 | B11: =Bond_2001!B12-Bond_2001!B11 -> -0.15 | C11: =Bond_2001!C12-Bond_2001!C11 -> -0.14 | D11: =Bond_2001!D12-Bond_2001!D11 -> 0 | E11: =Bond_2001!E12-Bond_2001!E11 -> -0.44 | F11: =Bond_2001!F12-Bond_2001!F11 -> -0.15 | G11: =Bond_2001!G12-Bond_2001!G11 -> -0.19 | H11: =Bond_2001!H12-Bond_2001!H11 -> -0.17 | I11: =Bond_2001!I12-Bond_2001!I11 -> -0.15 | ... Z11: =Bond_2001!Z12-Bond_2001!Z11 -> 0.0506
A12: 2001-12 | B12: =Bond_2001!B13-Bond_2001!B12 -> 0.25 | C12: =Bond_2001!C13-Bond_2001!C12 -> 0.22 | D12: =Bond_2001!D13-Bond_2001!D12 -> 0 | E12: =Bond_2001!E13-Bond_2001!E12 -> 0.03 | F12: =Bond_2001!F13-Bond_2001!F12 -> 0.29 | G12: =Bond_2001!G13-Bond_2001!G12 -> 0.3 | H12: =Bond_2001!H13-Bond_2001!H12 -> 0.23 | I12: =Bond_2001!I13-Bond_2001!I12 -> 0.21 | ... Z12: =Bond_2001!Z13-Bond_2001!Z12 -> 0.4622
A13: 2002-01 | B13: =Bond_2001!B14-Bond_2001!B13 -> 0.11 | C13: =Bond_2001!C14-Bond_2001!C13 -> 0.11 | D13: =Bond_2001!D14-Bond_2001!D13 -> 0 | E13: =Bond_2001!E14-Bond_2001!E13 -> -0.11 | F13: =Bond_2001!F14-Bond_2001!F13 -> 0.12 | G13: =Bond_2001!G14-Bond_2001!G13 -> 0.11 | H13: =Bond_2001!H14-Bond_2001!H13 -> 0.11 | I13: =Bond_2001!I14-Bond_2001!I13 -> 0.08 | ... Z13: =Bond_2001!Z14-Bond_2001!Z13 -> -0.0671
... A292: 2025-04 | B292: =Bond_2001!B293-Bond_2001!B292 -> -0.17 | C292: =Bond_2001!C293-Bond_2001!C292 -> -0.18 | D292: =Bond_2001!D293-Bond_2001!D292 -> -0.2 | E292: =Bond_2001!E293-Bond_2001!E292 -> -0.17 | F292: =Bond_2001!F293-Bond_2001!F292 -> -0.23 | G292: =Bond_2001!G293-Bond_2001!G292 -> -0.14 | H292: =Bond_2001!H293-Bond_2001!H292 -> -0.16 | I292: =Bond_2001!I293-Bond_2001!I292 -> -0.16 | ... Z292: =Bond_2001!Z293-Bond_2001!Z292 -> 0.0404

Sheet Bond_2015_diff
A1: Time | B1: AT | C1: BE | D1: BG | E1: CY | F1: CZ | G1: DE | H1: DK | I1: EL | J1: ES | K1: FI | L1: FR | M1: HR | N1: HU | O1: IE | P1: IT | Q1: LT | R1: LU | S1: LV | T1: MT | U1: NL | V1: PL | W1: PT | X1: RO | Y1: SE | Z1: SI | AA1: SK | AB1: UK | AC1: JP | AD1: TR | AE1: US
A2: 2015-05 | B2: =Bond_2015!B3-Bond_2015!B2 -> 0.44 | C2: =Bond_2015!C3-Bond_2015!C2 -> 0.44 | D2: =Bond_2015!D3-Bond_2015!D2 -> 0 | E2: =Bond_2015!E3-Bond_2015!E2 -> -2.04 | F2: =Bond_2015!F3-Bond_2015!F2 -> 0.34 | G2: =Bond_2015!G3-Bond_2015!G2 -> 0.44 | H2: =Bond_2015!H3-Bond_2015!H2 -> 0.48 | I2: =Bond_2015!I3-Bond_2015!I2 -> -1.05 | ... AE2: =Bond_2015!AE3-Bond_2015!AE2 -> 0.272
A3: 2015-06 | B3: =Bond_2015!B4-Bond_2015!B3 -> 0.33 | C3: =Bond_2015!C4-Bond_2015!C3 -> 0.35 | D3: =Bond_2015!D4-Bond_2015!D3 -> 0 | E3: =Bond_2015!E4-Bond_2015!E3 -> -0.07 | F3: =Bond_2015!F4-Bond_2015!F3 -> 0.41 | G3: =Bond_2015!G4-Bond_2015!G3 -> 0.23 | H3: =Bond_2015!H4-Bond_2015!H3 -> 0.27 | I3: =Bond_2015!I4-Bond_2015!I3 -> 0.48 | ... AE3: =Bond_2015!AE4-Bond_2015!AE3 -> 0.1629
A4: 2015-07 | B4: =Bond_2015!B5-Bond_2015!B4 -> 0.02 | C4: =Bond_2015!C5-Bond_2015!C4 -> -0.06 | D4: =Bond_2015!D5-Bond_2015!D4 -> 0 | E4: =Bond_2015!E5-Bond_2015!E4 -> -0.2 | F4: =Bond_2015!F5-Bond_2015!F4 -> -0.04 | G4: =Bond_2015!G5-Bond_2015!G4 -> -0.08 | H4: =Bond_2015!H5-Bond_2015!H4 -> -0.06 | I4: =Bond_2015!I5-Bond_2015!I4 -> 0 | ... AE4: =Bond_2015!AE5-Bond_2015!AE4 -> -0.0439
A5: 2015-08 | B5: =Bond_2015!B6-Bond_2015!B5 -> -0.12 | C5: =Bond_2015!C6-Bond_2015!C5 -> -0.15 | D5: =Bond_2015!D6-Bond_2015!D5 -> 0 | E5: =Bond_2015!E6-Bond_2015!E5 -> 0 | F5: =Bond_2015!F6-Bond_2015!F5 -> -0.23 | G5: =Bond_2015!G6-Bond_2015!G5 -> -0.1 | H5: =Bond_2015!H6-Bond_2015!H5 -> -0.1 | I5: =Bond_2015!I6-Bond_2015!I5 -> -1.17 | ... AE5: =Bond_2015!AE6-Bond_2015!AE5 -> -0.1549
A6: 2015-09 | B6: =Bond_2015!B7-Bond_2015!B6 -> 0.01 | C6: =Bond_2015!C7-Bond_2015!C6 -> 0.01 | D6: =Bond_2015!D7-Bond_2015!D6 -> 0 | E6: =Bond_2015!E7-Bond_2015!E6 -> 0.01 | F6: =Bond_2015!F7-Bond_2015!F6 -> -0.06 | G6: =Bond_2015!G7-Bond_2015!G6 -> 0.04 | H6: =Bond_2015!H7-Bond_2015!H6 -> 0.09 | I6: =Bond_2015!I7-Bond_2015!I6 -> -1.72 | ... AE6: =Bond_2015!AE7-Bond_2015!AE6 -> 0.0054
A7: 2015-10 | B7: =Bond_2015!B8-Bond_2015!B7 -> -0.14 | C7: =Bond_2015!C8-Bond_2015!C7 -> -0.16 | D7: =Bond_2015!D8-Bond_2015!D7 -> 0 | E7: =Bond_2015!E8-Bond_2015!E7 -> -0.06 | F7: =Bond_2015!F8-Bond_2015!F7 -> -0.12 | G7: =Bond_2015!G8-Bond_2015!G7 -> -0.13 | H7: =Bond_2015!H8-Bond_2015!H7 -> -0.1 | I7: =Bond_2015!I8-Bond_2015!I7 -> -0.73 | ... AE7: =Bond_2015!AE8-Bond_2015!AE7 -> -0.1087
A8: 2015-11 | B8: =Bond_2015!B9-Bond_2015!B8 -> -0.01 | C8: =Bond_2015!C9-Bond_2015!C8 -> -0.01 | D8: =Bond_2015!D9-Bond_2015!D8 -> 0.63 | E8: =Bond_2015!E9-Bond_2015!E8 -> 0.36 | F8: =Bond_2015!F9-Bond_2015!F8 -> -0.07 | G8: =Bond_2015!G9-Bond_2015!G8 -> 0 | H8: =Bond_2015!H9-Bond_2015!H8 -> -0.02 | I8: =Bond_2015!I9-Bond_2015!I8 -> -0.4 | ... AE8: =Bond_2015!AE9-Bond_2015!AE8 -> 0.2009
A9: 2015-12 | B9: =Bond_2015!B10-Bond_2015!B9 -> 0.04 | C9: =Bond_2015!C10-Bond_2015!C9 -> 0.05 | D9: =Bond_2015!D10-Bond_2015!D9 -> -0.56 | E9: =Bond_2015!E10-Bond_2015!E9 -> -0.13 | F9: =Bond_2015!F10-Bond_2015!F9 -> 0 | G9: =Bond_2015!G10-Bond_2015!G9 -> 0.03 | H9: =Bond_2015!H10-Bond_2015!H9 -> 0.02 | I9: =Bond_2015!I10-Bond_2015!I9 -> 0.8 | ... AE9: =Bond_2015!AE10-Bond_2015!AE9 -> -0.0224
A10: 2016-01 | B10: =Bond_2015!B11-Bond_2015!B10 -> -0.09 | C10: =Bond_2015!C11-Bond_2015!C10 -> -0.03 | D10: =Bond_2015!D11-Bond_2015!D10 -> 0.01 | E10: =Bond_2015!E11-Bond_2015!E10 -> -0.05 | F10: =Bond_2015!F11-Bond_2015!F10 -> 0.13 | G10: =Bond_2015!G11-Bond_2015!G10 -> -0.12 | H10: =Bond_2015!H11-Bond_2015!H10 -> -0.04 | I10: =Bond_2015!I11-Bond_2015!I10 -> 0.87 | ... AE10: =Bond_2015!AE11-Bond_2015!AE10 -> -0.1598
A11: 2016-02 | B11: =Bond_2015!B12-Bond_2015!B11 -> -0.24 | C11: =Bond_2015!C12-Bond_2015!C11 -> -0.14 | D11: =Bond_2015!D12-Bond_2015!D11 -> 0.23 | E11: =Bond_2015!E12-Bond_2015!E11 -> 0.18 | F11: =Bond_2015!F12-Bond_2015!F11 -> -0.16 | G11: =Bond_2015!G12-Bond_2015!G11 -> -0.26 | H11: =Bond_2015!H12-Bond_2015!H11 -> -0.24 | I11: =Bond_2015!I12-Bond_2015!I11 -> 1.33 | ... AE11: =Bond_2015!AE12-Bond_2015!AE11 -> -0.304
A12: 2016-03 | B12: =Bond_2015!B13-Bond_2015!B12 -> -0.07 | C12: =Bond_2015!C13-Bond_2015!C12 -> -0.1 | D12: =Bond_2015!D13-Bond_2015!D12 -> -0.01 | E12: =Bond_2015!E13-Bond_2015!E12 -> 0.01 | F12: =Bond_2015!F13-Bond_2015!F12 -> -0.11 | G12: =Bond_2015!G13-Bond_2015!G12 -> 0 | H12: =Bond_2015!H13-Bond_2015!H12 -> -0.04 | I12: =Bond_2015!I13-Bond_2015!I12 -> -1.29 | ... AE12: =Bond_2015!AE13-Bond_2015!AE12 -> 0.1122
A13: 2016-04 | B13: =Bond_2015!B14-Bond_2015!B13 -> -0.08 | C13: =Bond_2015!C14-Bond_2015!C13 -> -0.07 | D13: =Bond_2015!D14-Bond_2015!D13 -> -0.22 | E13: =Bond_2015!E14-Bond_2015!E13 -> -0.02 | F13: =Bond_2015!F14-Bond_2015!F13 -> 0.08 | G13: =Bond_2015!G14-Bond_2015!G13 -> -0.04 | H13: =Bond_2015!H14-Bond_2015!H13 -> -0.11 | I13: =Bond_2015!I14-Bond_2015!I13 -> -0.09 | ... AE13: =Bond_2015!AE14-Bond_2015!AE13 -> -0.0867
... A121: 2025-04 | B121: =Bond_2015!B122-Bond_2015!B121 -> -0.17 | C121: =Bond_2015!C122-Bond_2015!C121 -> -0.18 | D121: =Bond_2015!D122-Bond_2015!D121 -> 0 | E121: =Bond_2015!E122-Bond_2015!E121 -> -0.2 | F121: =Bond_2015!F122-Bond_2015!F121 -> -0.17 | G121: =Bond_2015!G122-Bond_2015!G121 -> -0.23 | H121: =Bond_2015!H122-Bond_2015!H121 -> -0.14 | I121: =Bond_2015!I122-Bond_2015!I121 -> -0.16 | ... AE121: =Bond_2015!AE122-Bond_2015!AE121 -> 0.0404

Sheet Bond_2015
A1: Time | B1: AT | C1: BE | D1: BG | E1: CY | F1: CZ | G1: DE | H1: DK | I1: EL | J1: ES | K1: FI | L1: FR | M1: HR | N1: HU | O1: IE | P1: IT | Q1: LT | R1: LU | S1: LV | T1: MT | U1: NL | V1: PL | W1: PT | X1: RO | Y1: SE | Z1: SI | AA1: SK | AB1: UK | AC1: JP | AD1: TR | AE1: US
A2: 2015-04 | B2: 0.29 | C2: 0.42 | D2: 2.36 | E2: 6 | F2: 0.26 | G2: 0.12 | H2: 0.25 | I2: 12 | J2: 1.31 | K2: 0.27 | L2: 0.44 | M2: 3.17 | N2: 3.28 | O2: 0.73 | P2: 1.36 | Q2: 0.58 | R2: 0.06 | S2: 0.42 | T2: 1.15 | U2: 0.31 | V2: 2.37 | W2: 1.87 | X2: 3.25 | Y2: 0.34 | Z2: 1.06 | AA2: 0.96 | AB2: 1.65 | AC2: 0.3294 | AD2: 8.73 | AE2: 1.9249
A3: 2015-05 | B3: 0.73 | C3: 0.86 | D3: 2.36 | E3: 3.96 | F3: 0.6 | G3: 0.56 | H3: 0.73 | I3: 10.95 | J3: 1.78 | K3: 0.72 | L3: 0.89 | M3: 2.98 | N3: 3.59 | O3: 1.25 | P3: 1.81 | Q3: 0.99 | R3: 0.42 | S3: 0.84 | T3: 1.5 | U3: 0.75 | V3: 2.82 | W3: 2.41 | X3: 3.45 | Y3: 0.75 | Z3: 1.59 | AA3: 0.92 | AB3: 1.94 | AC3: 0.402 | AD3: 9.21 | AE3: 2.1969
A4: 2015-06 | B4: 1.06 | C4: 1.21 | D4: 2.36 | E4: 3.89 | F4: 1.01 | G4: 0.79 | H4: 1 | I4: 11.43 | J4: 2.22 | K4: 1.01 | L4: 1.2 | M4: 3.07 | N4: 3.86 | O4: 1.65 | P4: 2.2 | Q4: 1.41 | R4: 0.65 | S4: 1.28 | T4: 1.79 | U4: 1.05 | V4: 3.19 | W4: 2.93 | X4: 3.84 | Y4: 0.99 | Z4: 2.13 | AA4: 1.15 | AB4: 2.06 | AC4: 0.469 | AD4: 9.48 | AE4: 2.3598
A5: 2015-07 | B5: 1.08 | C5: 1.15 | D5: 2.36 | E5: 3.69 | F5: 0.97 | G5: 0.71 | H5: 0.94 | I5: =11.43 -> 11.43 | J5: 2.1 | K5: 0.95 | L5: 1.11 | M5: 3.94 | N5: 3.72 | O5: 1.47 | P5: 2.04 | Q5: 1.64 | R5: 0.56 | S5: 1.25 | T5: 1.78 | U5: 0.99 | V5: 3.16 | W5: 2.74 | X5: 3.99 | Y5: 0.81 | Z5: 2.43 | AA5: 1.25 | AB5: 2.03 | AC5: 0.4408 | AD5: 9.51 | AE5: 2.3159
A6: 2015-08 | B6: 0.96 | C6: 1 | D6: 2.36 | E6: 3.69 | F6: 0.74 | G6: 0.61 | H6: 0.84 | I6: 10.26 | J6: 1.96 | K6: 0.82 | L6: 1.01 | M6: 3.9 | N6: 3.61 | O6: 1.29 | P6: 1.84 | Q6: 1.64 | R6: 0.45 | S6: 0.96 | T6: 1.57 | U6: 0.85 | V6: 2.88 | W6: 2.52 | X6: 3.86 | Y6: 0.66 | Z6: 2.07 | AA6: 0.99 | AB6: 1.86 | AC6: 0.387 | AD6: 9.98 | AE6: 2.161
A7: 2015-09 | B7: 0.97 | C7: 1.01 | D7: 2.36 | E7: 3.7 | F7: 0.68 | G7: 0.65 | H7: 0.93 | I7: 8.54 | J7: 2.03 | K7: 0.9 | L7: 1 | M7: 3.91 | N7: 3.5 | O7: 1.31 | P7: 1.92 | Q7: 1.64 | R7: 0.43 | S7: 1.03 | T7: 1.61 | U7: 0.87 | V7: 2.91 | W7: 2.59 | X7: 3.73 | Y7: 0.71 | Z7: 2.05 | AA7: 0.89 | AB7: 1.85 | AC7: 0.3625 | AD7: 10.67 | AE7: 2.1664
A8: 2015-10 | B8: 0.83 | C8: 0.85 | D8: 2.36 | E8: 3.64 | F8: 0.56 | G8: 0.52 | H8: 0.83 | I8: 7.81 | J8: 1.73 | K8: 0.81 | L8: 0.87 | M8: 3.93 | N8: 3.28 | O8: 1.14 | P8: 1.7 | Q8: 1.64 | R8: 0.31 | S8: 1.07 | T8: 1.37 | U8: 0.73 | V8: 2.66 | W8: 2.41 | X8: 3.47 | Y8: 0.66 | Z8: 1.8 | AA8: 0.75 | AB8: 1.81 | AC8: 0.3194 | AD8: 10.2 | AE8: 2.0577
A9: 2015-11 | B9: 0.82 | C9: 0.84 | D9: 2.99 | E9: 4 | F9: 0.49 | G9: 0.52 | H9: 0.81 | I9: 7.41 | J9: 1.72 | K9: 0.81 | L9: 0.88 | M9: 3.86 | N9: 3.34 | O9: 1.1 | P9: 1.57 | Q9: 1.57 | R9: 0.25 | S9: 1.19 | T9: 1.29 | U9: 0.72 | V9: 2.73 | W9: 2.57 | X9: 3.49 | Y9: 0.8 | Z9: 1.66 | AA9: 0.71 | AB9: 1.94 | AC9: 0.3129 | AD9: 9.89 | AE9: 2.2586
A10: 2015-12 | B10: 0.86 | C10: 0.89 | D10: 2.43 | E10: 3.87 | F10: 0.49 | G10: 0.55 | H10: 0.83 | I10: 8.21 | J10: 1.69 | K10: 0.86 | L10: 0.93 | M10: 3.92 | N10: 3.47 | O10: 1.11 | P10: 1.58 | Q10: 1.49 | R10: 0.27 | S10: 1.08 | T10: 1.29 | U10: 0.75 | V10: 2.96 | W10: 2.49 | X10: 3.62 | Y10: 0.93 | Z10: 1.61 | AA10: 0.72 | AB10: 1.87 | AC10: 0.3003 | AD10: 10.59 | AE10: 2.2362
A11: 2016-01 | B11: 0.77 | C11: 0.86 | D11: 2.44 | E11: 3.82 | F11: 0.62 | G11: 0.43 | H11: 0.79 | I11: 9.08 | J11: 1.72 | K11: 0.78 | L11: 0.84 | M11: 3.84 | N11: 3.36 | O11: 1.05 | P11: 1.53 | Q11: 1.47 | R11: 0.72 | S11: 1.05 | T11: 1.25 | U11: 0.65 | V11: 3 | W11: 2.71 | X11: 3.6 | Y11: 1.02 | Z11: 1.61 | AA11: 0.71 | AB11: 1.73 | AC11: 0.2242 | AD11: 11.12 | AE11: 2.0764
A12: 2016-02 | B12: 0.53 | C12: 0.72 | D12: 2.67 | E12: 4 | F12: 0.46 | G12: 0.17 | H12: 0.55 | I12: 10.41 | J12: 1.72 | K12: 0.53 | L12: 0.59 | M12: 3.68 | N12: 3.36 | O12: 0.99 | P12: 1.56 | Q12: 1.42 | R12: 0.43 | S12: 0.88 | T12: 1.16 | U12: 0.37 | V12: 3.03 | W12: 3.23 | X12: 3.33 | Y12: 0.77 | Z12: 1.59 | AA12: 0.56 | AB12: 1.44 | AC12: 0.0221 | AD12: 10.77 | AE12: 1.7724
A13: 2016-03 | B13: 0.46 | C13: 0.62 | D13: 2.66 | E13: 4.01 | F13: 0.35 | G13: 0.17 | H13: 0.51 | I13: 9.12 | J13: 1.54 | K13: 0.53 | L13: 0.51 | M13: 3.66 | N13: 3.13 | O13: 0.85 | P13: 1.38 | Q13: 1.42 | R13: 0.42 | S13: 0.71 | T13: 1.03 | U13: 0.32 | V13: 2.89 | W13: 2.84 | X13: 3.34 | Y13: 0.82 | Z13: 1.48 | AA13: 0.43 | AB13: 1.46 | AC13: -0.0557 | AD13: 10.23 | AE13: 1.8846
A14: 2016-04 | B14: 0.38 | C14: 0.55 | D14: 2.44 | E14: 3.99 | F14: 0.43 | G14: 0.13 | H14: 0.4 | I14: 9.03 | J14: 1.53 | K14: 0.46 | L14: 0.51 | M14: 3.62 | N14: 3.02 | O14: 0.86 | P14: 1.44 | Q14: 1.31 | R14: 0.34 | S14: 0.61 | T14: 1 | U14: 0.4 | V14: 2.95 | W14: 3.13 | X14: 3.43 | Y14: 0.81 | Z14: 1.37 | AA14: 0.38 | AB14: 1.48 | AC14: -0.0861 | AD14: 9.54 | AE14: 1.7979
A15: 2016-05 | B15: 0.37 | C15: 0.55 | D15: 2.37 | E15: 3.89 | F15: 0.46 | G15: 0.13 | H15: 0.41 | I15: 7.64 | J15: 1.57 | K15: 0.45 | L15: 0.51 | M15: 3.52 | N15: 3.35 | O15: 0.84 | P15: 1.53 | Q15: 0.86 | R15: 0.33 | S15: 0.51 | T15: 1.02 | U15: 0.38 | V15: 3.04 | W15: 3.15 | X15: 3.43 | Y15: 0.77 | Z15: 1.41 | AA15: 0.41 | AB15: 1.43 | AC15: -0.1013 | AD15: 9.96 | AE15: 1.803
A16: 2016-06 | B16: 0.33 | C16: 0.43 | D16: 2.4 | E16: 3.82 | F16: 0.45 | G16: -0.02 | H16: 0.23 | I16: 7.92 | J16: 1.48 | K16: 0.33 | L16: 0.39 | M16: 3.68 | N16: 3.31 | O16: 0.76 | P16: 1.45 | Q16: 0.86 | R16: 0.17 | S16: 0.48 | T16: 0.95 | U16: 0.25 | V16: 3.11 | W16: 3.2 | X16: 3.48 | Y16: 0.52 | Z16: 1.36 | AA16: 0.77 | AB16: 1.18 | AC16: -0.1538 | AD16: 9.62 | AE16: 1.6414
A17: 2016-07 | B17: 0.16 | C17: 0.2 | D17: 2.39 | E17: 3.87 | F17: 0.37 | G17: -0.15 | H17: 0.07 | I17: 7.99 | J17: 1.17 | K17: 0.12 | L17: 0.17 | M17: 3.75 | N17: 2.88 | O17: 0.47 | P17: 1.23 | Q17: 0.86 | R17: 0 | S17: 0.3 | T17: 0.76 | U17: 0.06 | V17: 2.89 | W17: 3.06 | X17: 3.14 | Y17: 0.17 | Z17: 0.95 | AA17: 0.49 | AB17: 0.79 | AC17: -0.2491 | AD17: 9.56 | AE17: 1.495
... A122: 2025-04 | B122: 2.98 | C122: 3.14 | D122: 3.93 | E122: 2.9 | F122: 4.09 | G122: 2.51 | H122: 2.31 | I122: 3.44 | J122: 3.23 | K122: 2.94 | L122: 3.26 | M122: 3.05 | N122: 6.99 | O122: 2.9 | P122: 3.71 | Q122: 2.88 | R122: 2.87 | S122: 3.36 | T122: 3.37 | U122: 2.71 | V122: 5.3 | W122: 3.11 | X122: 6.63 | Y122: 2.42 | Z122: 3.1 | AA122: 3.49 | AB122: 4.58 | AC122: 1.3154 | AD122: 33.94687 | AE122: 4.318

Sheet Bond_2001
A1: Time | B1: AT | C1: BE | D1: CY | E1: CZ | F1: DE | G1: DK | H1: EL | I1: ES | J1: FI | K1: FR | L1: HU | M1: IE | N1: IT | O1: LT | P1: LU | Q1: LV | R1: MT | S1: NL | T1: PL | U1: PT | V1: SE | W1: SK | X1: UK | Y1: JP | Z1: US
A2: 2001-01 | B2: 5.1 | C2: 5.16 | D2: 7.68 | E2: 6.82 | F2: 4.8 | G2: 5.09 | H2: 5.35 | I2: 5.08 | J2: 5.02 | K2: 4.94 | L2: 8.05 | M2: 5.03 | N2: 5.18 | O2: 9.31 | P2: 5.06 | Q2: 7.64 | R2: 6.11 | S2: 4.93 | T2: 10.43 | U2: 5.16 | V2: 4.89 | W2: 8.25 | X2: 4.94 | Y2: 1.5508 | Z2: 5.1447
A3: 2001-02 | B3: 5.1 | C3: 5.16 | D3: 7.68 | E3: 6.5 | F3: 4.78 | G3: 5.06 | H3: 5.35 | I3: 5.12 | J3: 5.02 | K3: 4.93 | L3: 8.34 | M3: 5.01 | N3: 5.18 | O3: 9.77 | P3: 5.08 | Q3: 7.82 | R3: 6.11 | S3: 4.92 | T3: 10.23 | U3: 5.14 | V3: 4.86 | W3: 8.17 | X3: 4.95 | Y3: 1.4352 | Z3: 5.1015
A4: 2001-03 | B4: 5.01 | C4: 5.08 | D4: 7.66 | E4: 6.24 | F4: 4.67 | G4: 4.95 | H4: 5.28 | I4: 5.04 | J4: 4.94 | K4: 4.84 | L4: 8.57 | M4: 4.92 | N4: 5.13 | O4: 8.64 | P4: 4.93 | Q4: 7.9 | R4: 6.11 | S4: 4.83 | T4: 10.62 | U4: 5.09 | V4: 4.75 | W4: 8.09 | X4: 4.82 | Y4: 1.1954 | Z4: 4.885
A5: 2001-04 | B5: 5.16 | C5: 5.21 | D5: 7.63 | E5: 6.25 | F5: 4.83 | G5: 5.14 | H5: 5.39 | I5: 5.18 | J5: 5.1 | K5: 5 | L5: 8.61 | M5: 5.09 | N5: 5.28 | O5: 8.5 | P5: 5.05 | Q5: 7.9 | R5: 6.11 | S5: 5.02 | T5: 10.61 | U5: 5.27 | V5: 4.93 | W5: 8 | X5: 5.03 | Y5: 1.358 | Z5: 5.1278
A6: 2001-05 | B6: 5.34 | C6: 5.38 | D6: 7.71 | E6: 6.49 | F6: 5.05 | G6: 5.35 | H6: 5.54 | I6: 5.36 | J6: 5.29 | K6: 5.21 | L6: 8.07 | M6: 5.28 | N6: 5.45 | O6: 8.46 | P6: 5.3 | Q6: 7.54 | R6: 6.11 | S6: 5.22 | T6: 11.26 | U6: 5.42 | V6: 5.27 | W6: 8.02 | X6: 5.21 | Y6: 1.2847 | Z6: 5.368
A7: 2001-06 | B7: 5.27 | C7: 5.33 | D7: 7.7 | E7: 6.72 | F7: 5 | G7: 5.33 | H7: 5.48 | I7: 5.33 | J7: 5.26 | K7: 5.15 | L7: 7.8 | M7: 5.23 | N7: 5.4 | O7: 8.46 | P7: 5.15 | Q7: 7.6 | R7: 6.14 | S7: 5.17 | T7: 11.66 | U7: 5.38 | V7: 5.38 | W7: 8.05 | X7: 5.3 | Y7: 1.2016 | Z7: 5.2586
A8: 2001-07 | B8: 5.29 | C8: 5.35 | D8: 7.69 | E8: 6.85 | F8: 5.02 | G8: 5.32 | H8: 5.51 | I8: 5.35 | J8: 5.27 | K8: 5.15 | L8: 7.77 | M8: 5.23 | N8: 5.42 | O8: 8.46 | P8: 5.05 | Q8: 7.75 | R8: 6.17 | S8: 5.17 | T8: 11.79 | U8: 5.39 | V8: 5.42 | W8: 8.04 | X8: 5.3 | Y8: 1.3289 | Z8: 5.2252
A9: 2001-08 | B9: 5.1 | C9: 5.15 | D9: 7.55 | E9: 6.76 | F9: 4.82 | G9: 5.12 | H9: 5.33 | I9: 5.16 | J9: 5.06 | K9: 4.95 | L9: 7.76 | M9: 5.01 | N9: 5.22 | O9: 8.01 | P9: 4.81 | Q9: 7.66 | R9: 6.29 | S9: 4.98 | T9: 11.86 | U9: 5.19 | V9: 5.16 | W9: 7.99 | X9: 5.07 | Y9: 1.3654 | Z9: 4.9724
A10: 2001-09 | B10: 5.08 | C10: 5.14 | D10: 7.55 | E10: 6.47 | F10: 4.81 | G10: 5.11 | H10: 5.31 | I10: 5.14 | J10: 5.06 | K10: 4.94 | L10: 7.94 | M10: 5.01 | N10: 5.2 | O10: 7.99 | P10: 4.67 | Q10: 7.58 | R10: 6.3 | S10: 4.98 | T10: 11.49 | U10: 5.17 | V10: 5.26 | W10: 8.1 | X10: 5.02 | Y10: 1.4058 | Z10: 4.7551
A11: 2001-10 | B11: 4.85 | C11: 4.89 | D11: 7.55 | E11: 5.84 | F11: 4.6 | G11: 4.86 | H11: 5.07 | I11: 4.91 | J11: 4.83 | K11: 4.72 | L11: 7.98 | M11: 4.77 | N11: 4.96 | O11: 7.62 | P11: 4.41 | Q11: 7.48 | R11: 6.3 | S11: 4.77 | T11: 10.31 | U11: 4.92 | V11: 5.17 | W11: 8.08 | X11: 4.86 | Y11: 1.3661 | Z11: 4.5545
A12: 2001-11 | B12: 4.7 | C12: 4.75 | D12: 7.55 | E12: 5.4 | F12: 4.45 | G12: 4.67 | H12: 4.9 | I12: 4.76 | J12: 4.69 | K12: 4.57 | L12: 7.38 | M12: 4.63 | N12: 4.8 | O12: 6.28 | P12: 4.29 | Q12: 7.08 | R12: 6.27 | S12: 4.62 | T12: 9.04 | U12: 4.76 | V12: 4.96 | W12: 7.97 | X12: 4.67 | Y12: 1.341 | Z12: 4.6051
A13: 2001-12 | B13: 4.95 | C13: 4.97 | D13: 7.55 | E13: 5.43 | F13: 4.74 | G13: 4.97 | H13: 5.13 | I13: 4.97 | J13: 4.98 | K13: 4.87 | L13: 7.07 | M13: 4.93 | N13: 5.05 | O13: 6.34 | P13: 4.51 | Q13: 6.93 | R13: 6.24 | S13: 4.89 | T13: 8.88 | U13: 5.01 | V13: 5.24 | W13: 7.75 | X13: 4.94 | Y13: 1.3532 | Z13: 5.0673
... A175: 2015-06 | B175: 1.06 | C175: 1.21 | D175: 3.89 | E175: 1.01 | F175: 0.79 | G175: 1 | H175: 11.43 | I175: 2.22 | J175: 1.01 | K175: 1.2 | L175: 3.86 | M175: 1.65 | N175: 2.2 | O175: 1.41 | P175: 0.65 | Q175: 1.28 | R175: 1.79 | S175: 1.05 | T175: 3.19 | U175: 2.93 | V175: 0.99 | W175: 1.15 | X175: 2.06 | Y175: 0.469 | Z175: 2.3598
A176: 2015-07 | B176: 1.08 | C176: 1.15 | D176: 3.69 | E176: 0.97 | F176: 0.71 | G176: 0.94 | H176: =H175 -> 11.43 | I176: 2.1 | J176: 0.95 | K176: 1.11 | L176: 3.72 | M176: 1.47 | N176: 2.04 | O176: 1.64 | P176: 0.56 | Q176: 1.25 | R176: 1.78 | S176: 0.99 | T176: 3.16 | U176: 2.74 | V176: 0.81 | W176: 1.25 | X176: 2.03 | Y176: 0.4408 | Z176: 2.3159
A177: 2015-08 | B177: 0.96 | C177: 1 | D177: 3.69 | E177: 0.74 | F177: 0.61 | G177: 0.84 | H177: 10.26 | I177: 1.96 | J177: 0.82 | K177: 1.01 | L177: 3.61 | M177: 1.29 | N177: 1.84 | O177: 1.64 | P177: 0.45 | Q177: 0.96 | R177: 1.57 | S177: 0.85 | T177: 2.88 | U177: 2.52 | V177: 0.66 | W177: 0.99 | X177: 1.86 | Y177: 0.387 | Z177: 2.161
A178: 2015-09 | B178: 0.97 | C178: 1.01 | D178: 3.7 | E178: 0.68 | F178: 0.65 | G178: 0.93 | H178: 8.54 | I178: 2.03 | J178: 0.9 | K178: 1 | L178: 3.5 | M178: 1.31 | N178: 1.92 | O178: 1.64 | P178: 0.43 | Q178: 1.03 | R178: 1.61 | S178: 0.87 | T178: 2.91 | U178: 2.59 | V178: 0.71 | W178: 0.89 | X178: 1.85 | Y178: 0.3625 | Z178: 2.1664
A179: 2015-10 | B179: 0.83 | C179: 0.85 | D179: 3.64 | E179: 0.56 | F179: 0.52 | G179: 0.83 | H179: 7.81 | I179: 1.73 | J179: 0.81 | K179: 0.87 | L179: 3.28 | M179: 1.14 | N179: 1.7 | O179: 1.64 | P179: 0.31 | Q179: 1.07 | R179: 1.37 | S179: 0.73 | T179: 2.66 | U179: 2.41 | V179: 0.66 | W179: 0.75 | X179: 1.81 | Y179: 0.3194 | Z179: 2.0577
A180: 2015-11 | B180: 0.82 | C180: 0.84 | D180: 4 | E180: 0.49 | F180: 0.52 | G180: 0.81 | H180: 7.41 | I180: 1.72 | J180: 0.81 | K180: 0.88 | L180: 3.34 | M180: 1.1 | N180: 1.57 | O180: 1.57 | P180: 0.25 | Q180: 1.19 | R180: 1.29 | S180: 0.72 | T180: 2.73 | U180: 2.57 | V180: 0.8 | W180: 0.71 | X180: 1.94 | Y180: 0.3129 | Z180: 2.2586
A181: 2015-12 | B181: 0.86 | C181: 0.89 | D181: 3.87 | E181: 0.49 | F181: 0.55 | G181: 0.83 | H181: 8.21 | I181: 1.69 | J181: 0.86 | K181: 0.93 | L181: 3.47 | M181: 1.11 | N181: 1.58 | O181: 1.49 | P181: 0.27 | Q181: 1.08 | R181: 1.29 | S181: 0.75 | T181: 2.96 | U181: 2.49 | V181: 0.93 | W181: 0.72 | X181: 1.87 | Y181: 0.3003 | Z181: 2.2362
A182: 2016-01 | B182: 0.77 | C182: 0.86 | D182: 3.82 | E182: 0.62 | F182: 0.43 | G182: 0.79 | H182: 9.08 | I182: 1.72 | J182: 0.78 | K182: 0.84 | L182: 3.36 | M182: 1.05 | N182: 1.53 | O182: 1.47 | P182: 0.72 | Q182: 1.05 | R182: 1.25 | S182: 0.65 | T182: 3 | U182: 2.71 | V182: 1.02 | W182: 0.71 | X182: 1.73 | Y182: 0.2242 | Z182: 2.0764
A183: 2016-02 | B183: 0.53 | C183: 0.72 | D183: 4 | E183: 0.46 | F183: 0.17 | G183: 0.55 | H183: 10.41 | I183: 1.72 | J183: 0.53 | K183: 0.59 | L183: 3.36 | M183: 0.99 | N183: 1.56 | O183: 1.42 | P183: 0.43 | Q183: 0.88 | R183: 1.16 | S183: 0.37 | T183: 3.03 | U183: 3.23 | V183: 0.77 | W183: 0.56 | X183: 1.44 | Y183: 0.0221 | Z183: 1.7724
A184: 2016-03 | B184: 0.46 | C184: 0.62 | D184: 4.01 | E184: 0.35 | F184: 0.17 | G184: 0.51 | H184: 9.12 | I184: 1.54 | J184: 0.53 | K184: 0.51 | L184: 3.13 | M184: 0.85 | N184: 1.38 | O184: 1.42 | P184: 0.42 | Q184: 0.71 | R184: 1.03 | S184: 0.32 | T184: 2.89 | U184: 2.84 | V184: 0.82 | W184: 0.43 | X184: 1.46 | Y184: -0.0557 | Z184: 1.8846
A185: 2016-04 | B185: 0.38 | C185: 0.55 | D185: 3.99 | E185: 0.43 | F185: 0.13 | G185: 0.4 | H185: 9.03 | I185: 1.53 | J185: 0.46 | K185: 0.51 | L185: 3.02 | M185: 0.86 | N185: 1.44 | O185: 1.31 | P185: 0.34 | Q185: 0.61 | R185: 1 | S185: 0.4 | T185: 2.95 | U185: 3.13 | V185: 0.81 | W185: 0.38 | X185: 1.48 | Y185: -0.0861 | Z185: 1.7979
A186: 2016-05 | B186: 0.37 | C186: 0.55 | D186: 3.89 | E186: 0.46 | F186: 0.13 | G186: 0.41 | H186: 7.64 | I186: 1.57 | J186: 0.45 | K186: 0.51 | L186: 3.35 | M186: 0.84 | N186: 1.53 | O186: 0.86 | P186: 0.33 | Q186: 0.51 | R186: 1.02 | S186: 0.38 | T186: 3.04 | U186: 3.15 | V186: 0.77 | W186: 0.41 | X186: 1.43 | Y186: -0.1013 | Z186: 1.803
A187: 2016-06 | B187: 0.33 | C187: 0.43 | D187: 3.82 | E187: 0.45 | F187: -0.02 | G187: 0.23 | H187: 7.92 | I187: 1.48 | J187: 0.33 | K187: 0.39 | L187: 3.31 | M187: 0.76 | N187: 1.45 | O187: 0.86 | P187: 0.17 | Q187: 0.48 | R187: 0.95 | S187: 0.25 | T187: 3.11 | U187: 3.2 | V187: 0.52 | W187: 0.77 | X187: 1.18 | Y187: -0.1538 | Z187: 1.6414
A188: 2016-07 | B188: 0.16 | C188: 0.2 | D188: 3.87 | E188: 0.37 | F188: -0.15 | G188: 0.07 | H188: 7.99 | I188: 1.17 | J188: 0.12 | K188: 0.17 | L188: 2.88 | M188: 0.47 | N188: 1.23 | O188: 0.86 | P188: 0 | Q188: 0.3 | R188: 0.76 | S188: 0.06 | T188: 2.89 | U188: 3.06 | V188: 0.17 | W188: 0.49 | X188: 0.79 | Y188: -0.2491 | Z188: 1.495
... A293: 2025-04 | B293: 2.98 | C293: 3.14 | D293: 2.9 | E293: 4.09 | F293: 2.51 | G293: 2.31 | H293: 3.44 | I293: 3.23 | J293: 2.94 | K293: 3.26 | L293: 6.99 | M293: 2.9 | N293: 3.71 | O293: 2.88 | P293: 2.87 | Q293: 3.36 | R293: 3.37 | S293: 2.71 | T293: 5.3 | U293: 3.11 | V293: 2.42 | W293: 3.49 | X293: 4.58 | Y293: 1.3154 | Z293: 4.318

Sheet Bond_raw_EU
A1: Time | B1: AT | C1: BE | D1: BG | E1: CY | F1: CZ | G1: DE | H1: DK | I1: EA | J1: EE | K1: EL | L1: ES | M1: EU27_2020 | N1: FI | O1: FR | P1: HR | Q1: HU | R1: IE | S1: IT | T1: LT | U1: LU | V1: LV | W1: MT | X1: NL | Y1: PL | Z1: PT | AA1: RO | AB1: SE | AC1: SI | AD1: SK | AE1: UK | AF1: JP | AG1: TR | AH1: US
A2: 1980-01 | C2: 11.06 | G2: 8.06 | L2: 15.5 | O2: 11.68 | S2: 13.96 | AF2: 8.5 | AH2: 10.03
A3: 1980-02 | C3: 11.42 | G3: 8.39 | L3: 15.4 | O3: 13.4 | S3: 14.09 | AF3: 9.32 | AH3: 11.55
A4: 1980-03 | C4: 12.28 | G4: 9.37 | L4: 15.72 | O4: 13.47 | S4: 14.74 | AF4: 10 | AH4: 11.87
A5: 1980-04 | C5: 12.11 | G5: 9.36 | L5: 15.98 | O5: 13.02 | S5: 14.92 | AF5: 10.3 | AH5: 10.83
A6: 1980-05 | C6: 11.86 | G6: 8.59 | L6: 15.9 | O6: 12.91 | S6: 15.02 | AF6: 8.75 | AH6: 9.82
A7: 1980-06 | C7: 11.95 | G7: 8.18 | L7: 15.06 | O7: 12.93 | S7: 15.18 | AF7: 8.61 | AH7: 9.4
A8: 1980-07 | C8: 11.53 | G8: 7.95 | L8: 15.78 | O8: 12.89 | S8: 15.44 | AF8: 8.88 | AH8: 9.83
A9: 1980-08 | C9: 11.72 | G9: 7.84 | L9: 16.21 | O9: 12.84 | S9: 15.6 | AF9: 9.09 | AH9: 10.53
A10: 1980-09 | C10: 12.05 | G10: 8.17 | L10: 16.33 | O10: 13.26 | S10: 15.69 | AF10: 9.21 | AH10: 10.94
A11: 1980-10 | C11: 12.24 | G11: 8.36 | L11: 16.71 | O11: 13.73 | S11: 16.08 | AF11: 8.99 | AH11: 11.2
A12: 1980-11 | C12: 12.23 | G12: 8.7 | L12: 16.71 | O12: 13.71 | S12: 16.14 | AF12: 8.52 | AH12: 11.83
A13: 1980-12 | C13: 12.35 | G13: 8.86 | L13: 16.23 | O13: 13.69 | S13: 16.17 | AF13: 9.41 | AH13: 11.89
... A42: 1983-05 | C42: 11.7 | G42: 7.69 | L42: 17.02 | O42: 13.73 | S42: 18.29 | AF42: 7.61 | AH42: 10.21
A43: 1983-06 | C43: 11.67 | G43: 8.11 | H43: 14.28 | L43: 16.7 | O43: 13.67 | S43: 18.39 | AF43: 7.49 | AH43: 10.64
A44: 1983-07 | C44: 11.51 | G44: 8.24 | H44: 15.25 | L44: 16.94 | O44: 13.13 | S44: 18.42 | AF44: 7.59 | AH44: 11.1
A45: 1983-08 | C45: 11.5 | G45: 8.37 | H45: 15.36 | L45: 17.63 | O45: 13.21 | S45: 18.11 | AF45: 7.54 | AH45: 11.42
A46: 1983-09 | C46: 11.77 | G46: 8.48 | H46: 14.1 | L46: 17.75 | O46: 13.4 | S46: 17.79 | AF46: 7.28 | AH46: 11.26
A47: 1983-10 | C47: 11.75 | G47: 8.26 | H47: 14.53 | L47: 18.11 | O47: 13.42 | S47: 17.64 | AF47: 7.22 | AH47: 11.21
A48: 1983-11 | C48: 11.87 | G48: 8.31 | H48: 14.24 | L48: 18.1 | O48: 13.41 | S48: 17.78 | AF48: 7.09 | AH48: 11.32
A49: 1983-12 | C49: 12.18 | G49: 8.41 | H49: 13.76 | L49: 17.23 | O49: 13.32 | S49: 17.69 | AF49: 6.94 | AH49: 11.44
A50: 1984-01 | C50: 12.29 | G50: 8.38 | H50: 12.91 | L50: 17.19 | O50: 13.01 | S50: 16.92 | AE50: 10.77 | AF50: 6.94 | AH50: 11.29
A51: 1984-02 | C51: 12.41 | G51: 8.21 | H51: 13.36 | L51: 16.88 | O51: 13.05 | S51: 16.33 | AE51: 10.87 | AF51: 6.92 | AH51: 11.44
A52: 1984-03 | C52: 12.55 | G52: 8.12 | H52: 14.28 | L52: 17.27 | O52: 13.11 | S52: 15.68 | AE52: 10.66 | AF52: 6.63 | AH52: 11.9
A53: 1984-04 | C53: 12.39 | G53: 8.08 | H53: 15.01 | L53: 17.55 | O53: 12.85 | S53: 15.74 | AE53: 10.85 | AF53: 6.68 | AH53: 12.17
A54: 1984-05 | C54: 12.39 | G54: 8.24 | H54: 14.58 | L54: 17.57 | O54: 12.96 | S54: 15.75 | AE54: 11.38 | AF54: 7.27 | AH54: 12.89
A55: 1984-06 | C55: 12.4 | G55: 8.24 | H55: 14.85 | L55: 17.11 | O55: 13.12 | S55: 15.54 | AE55: 11.59 | AF55: 7.12 | AH55: 13
A56: 1984-07 | C56: 12.33 | G56: 8.24 | H56: 15.28 | L56: 16.95 | O56: 12.93 | S56: 15.18 | AE56: 12.07 | AF56: 7.15 | AH56: 12.82
A57: 1984-08 | C57: 12.16 | G57: 8.11 | H57: 14.63 | L57: 16.88 | O57: 12.48 | S57: 15.28 | AE57: 11.41 | AF57: 6.9 | AH57: 12.23
A58: 1984-09 | C58: 12.12 | G58: 7.9 | H58: 14.85 | L58: 16.42 | O58: 12.01 | S58: 15.64 | AE58: 11.23 | AF58: 6.79 | AH58: 11.97
A59: 1984-10 | C59: 12.13 | G59: 7.57 | H59: 14.66 | L59: 15.55 | O59: 10.86 | S59: 15.35 | AE59: 11.1 | AF59: 6.6 | AH59: 11.66
A60: 1984-11 | C60: 11.9 | G60: 7.26 | H60: 14.35 | L60: 14.98 | O60: 11.7 | S60: 15.25 | AE60: 10.73 | AF60: 6.36 | AH60: 11.25
A61: 1984-12 | C61: 11.84 | G61: 7.04 | H61: 14.36 | L61: 13.92 | O61: 11.79 | S61: 14.53 | AE61: 10.87 | AF61: 6.3 | AH61: 11.2
A62: 1985-01 | B62: 8 | C62: 11.75 | G62: 7.12 | H62: 14.18 | L62: 13.2 | O62: 11.38 | S62: 13.27 | U62: 9.9 | AE62: 11.36 | AF62: 6.28 | AH62: 11.15
A63: 1985-02 | B63: 8 | C63: 11.73 | G63: 7.59 | H63: 13.51 | L63: 13.22 | O63: 11.61 | S63: 13.29 | U63: 9.75 | AE63: 11.49 | AF63: 6.79 | AH63: 11.35
A64: 1985-03 | B64: 8.06 | C64: 11.73 | G64: 7.63 | H64: 12.97 | L64: 13.46 | O64: 11.56 | S64: 13.51 | U64: 9.7 | AE64: 11.33 | AF64: 6.6 | AH64: 11.78
A65: 1985-04 | B65: 8.08 | C65: 11.64 | G65: 7.31 | H65: 12.04 | L65: 13.4 | O65: 11.23 | S65: 13.57 | U65: 9.72 | AE65: 11.07 | AF65: 6.54 | AH65: 11.42
A66: 1985-05 | B66: 8.01 | C66: 11.45 | G66: 7.2 | H66: 12.06 | L66: 13.57 | O66: 11.04 | S66: 13.89 | U66: 9.72 | AE66: 11.23 | AF66: 6.37 | AH66: 10.96
A67: 1985-06 | B67: 7.87 | C67: 10.78 | G67: 7.05 | H67: 11.4 | L67: 13.79 | O67: 11.14 | S67: 13.91 | U67: 9.58 | AE67: 11.03 | AF67: 6.26 | AH67: 10.36
A68: 1985-07 | B68: 7.77 | C68: 10.67 | G68: 6.86 | H68: 10.57 | L68: 14.44 | O68: 10.99 | S68: 14.12 | U68: 9.34 | AE68: 10.77 | AF68: 6.25 | AH68: 10.51
...

Sheet Bond_raw_extra
A1: Time | B1: JP | C1: TR | D1: US
A2: 1973-01 | B2: 6.43
A3: 1973-02 | B3: 6.58
A4: 1973-03 | B4: 6.64
A5: 1973-04 | B5: 7.04
A6: 1973-05 | B6: 7.08
A7: 1973-06 | B7: 7.09
A8: 1973-07 | B8: 7.24
A9: 1973-08 | B9: 7.43
A10: 1973-09 | B10: 7.52
A11: 1973-10 | B11: 7.61
A12: 1973-11 | B12: 7.71
A13: 1973-12 | B13: 8.78
A14: 1974-01 | B14: 9 | D14: 6.56
A15: 1974-02 | B15: 8.94 | D15: 6.54
A16: 1974-03 | B16: 9.2 | D16: 6.81
A17: 1974-04 | B17: 9.16 | D17: 7.04
A18: 1974-05 | B18: 9.12 | D18: 7.07
A19: 1974-06 | B19: 9.18 | D19: 7.03
A20: 1974-07 | B20: 9.07 | D20: 7.18
A21: 1974-08 | B21: 9.33 | D21: 7.33
A22: 1974-09 | B22: 9.53 | D22: 7.3
A23: 1974-10 | B23: 9.41 | D23: 7.22
A24: 1974-11 | B24: 9.59 | D24: 6.93
A25: 1974-12 | B25: 9.6 | D25: 6.78
A26: 1975-01 | D26: 6.68
A27: 1975-02 | D27: 6.61
A28: 1975-03 | D28: 6.73
A29: 1975-04 | D29: 7.03
A30: 1975-05 | D30: 6.99
A31: 1975-06 | D31: 6.86
A32: 1975-07 | D32: 6.89
A33: 1975-08 | D33: 7.06
A34: 1975-09 | D34: 7.29
A35: 1975-10 | D35: 7.29
A36: 1975-11 | D36: 7.21
A37: 1975-12 | D37: 7.17
... A85: 1979-12 | D85: 9.59
A86: 1980-01 | B86: 8.5 | D86: 10.03
A87: 1980-02 | B87: 9.32 | D87: 11.55
...
